Traceback (most recent call last):
  File "/usr/local/Caskroom/miniconda/base/envs/kaggle/lib/python3.9/site-packages/jupyter_cache/executors/utils.py", line 51, in single_nb_execution
    executenb(
  File "/usr/local/Caskroom/miniconda/base/envs/kaggle/lib/python3.9/site-packages/nbclient/client.py", line 1117, in execute
    return NotebookClient(nb=nb, resources=resources, km=km, **kwargs).execute()
  File "/usr/local/Caskroom/miniconda/base/envs/kaggle/lib/python3.9/site-packages/nbclient/util.py", line 78, in wrapped
    return just_run(coro(*args, **kwargs))
  File "/usr/local/Caskroom/miniconda/base/envs/kaggle/lib/python3.9/site-packages/nbclient/util.py", line 57, in just_run
    return loop.run_until_complete(coro)
  File "/usr/local/Caskroom/miniconda/base/envs/kaggle/lib/python3.9/asyncio/base_events.py", line 642, in run_until_complete
    return future.result()
  File "/usr/local/Caskroom/miniconda/base/envs/kaggle/lib/python3.9/site-packages/nbclient/client.py", line 558, in async_execute
    await self.async_execute_cell(
  File "/usr/local/Caskroom/miniconda/base/envs/kaggle/lib/python3.9/site-packages/nbclient/client.py", line 862, in async_execute_cell
    self._check_raise_for_error(cell, exec_reply)
  File "/usr/local/Caskroom/miniconda/base/envs/kaggle/lib/python3.9/site-packages/nbclient/client.py", line 765, in _check_raise_for_error
    raise CellExecutionError.from_cell_and_msg(cell, exec_reply_content)
nbclient.exceptions.CellExecutionError: An error occurred while executing the following cell:
------------------
recall_for_forest = tpr_forest[np.argmax(fpr_forest >= fpr_90)]

plt.figure(figsize=(8, 6))
roc_auc = auc(fpr_forest, tpr_forest)
roc_display = RocCurveDisplay(fpr=fpr_forest, tpr=tpr_forest,
                              roc_auc=roc_auc).plot(ax=ax)

roc_display.line_(label="Random Forest")
plt.plot(fpr, tpr, "b:", linewidth=2, label="SGD")
plt.plot([fpr_90, fpr_90], [0., recall_90_precision], "r:")
plt.plot([0.0, fpr_90], [recall_90_precision, recall_90_precision], "r:")
plt.plot([fpr_90], [recall_90_precision], "ro")
plt.plot([fpr_90, fpr_90], [0., recall_for_forest], "r:")
plt.plot([fpr_90], [recall_for_forest], "ro")
plt.grid(True)
plt.legend(loc="lower right", fontsize=16)
plt.show()
------------------

[0;31m---------------------------------------------------------------------------[0m
[0;31mTypeError[0m                                 Traceback (most recent call last)
[0;32m/var/folders/93/795zm8c93m16_92qkk86t0_r0000gn/T/ipykernel_31445/889204161.py[0m in [0;36m<module>[0;34m[0m
[1;32m      6[0m                               roc_auc=roc_auc).plot(ax=ax)
[1;32m      7[0m [0;34m[0m[0m
[0;32m----> 8[0;31m [0mroc_display[0m[0;34m.[0m[0mline_[0m[0;34m([0m[0mlabel[0m[0;34m=[0m[0;34m"Random Forest"[0m[0;34m)[0m[0;34m[0m[0;34m[0m[0m
[0m[1;32m      9[0m [0mplt[0m[0;34m.[0m[0mplot[0m[0;34m([0m[0mfpr[0m[0;34m,[0m [0mtpr[0m[0;34m,[0m [0;34m"b:"[0m[0;34m,[0m [0mlinewidth[0m[0;34m=[0m[0;36m2[0m[0;34m,[0m [0mlabel[0m[0;34m=[0m[0;34m"SGD"[0m[0;34m)[0m[0;34m[0m[0;34m[0m[0m
[1;32m     10[0m [0mplt[0m[0;34m.[0m[0mplot[0m[0;34m([0m[0;34m[[0m[0mfpr_90[0m[0;34m,[0m [0mfpr_90[0m[0;34m][0m[0;34m,[0m [0;34m[[0m[0;36m0.[0m[0;34m,[0m [0mrecall_90_precision[0m[0;34m][0m[0;34m,[0m [0;34m"r:"[0m[0;34m)[0m[0;34m[0m[0;34m[0m[0m

[0;31mTypeError[0m: 'Line2D' object is not callable
TypeError: 'Line2D' object is not callable

